File: DATA/UKSAF/Pt4f.vms
VAMAS Surface Chemical Analysis Standard Data Transfer Format 1988 May 4
Not Specified
Not Specified
Not Specified
Not Specified
4
Casa Info Follows CasaXPS Version 2.3.27PR1.7
0
FileDesc:230809_Pt_Plate_004_Etch1
SourceAnalyserAngle: Not Specified
NORM
REGULAR
1
1
Exp Variable
d
0
0
0
0
1
Pt4f PE20
Pt #002
2023
8
9
8
8
56
0
10
Casa Info Follows
0
0
0
0
Pt #002 X Y [22307.5 , 37642.2]
X-ray spot-size: 100 um by 100 um
230809_Pt_Plate_004_Etch1
Standard  9/8/2023   08:08:56
C:\Users\gwilh\OneDrive - Imperial College London\Documents\MEGAsync\Conference\Harwell Workshop 2024\Workshop2024\Workshop2024\CasaXPSTipsAndTricks\PtFoil_Etch2000evMid.vms
XPS
0
KA1486
1486.68
27.84
1e+37
1e+37
1e+37
1e+37
FAT
20
1e+37
1e+37
1e+37
1e+37
1e+37
1e+37
1e+37
Pt
4f
-1
Kinetic Energy
eV
1396.68
0.1
2
0,0 Counts
d
Transmission
d
pulse counting
0.05
1
1e+37
1e+37
1e+37
1e+37
2
MFP Exponent
d
-0.6
ESCAPE DEPTH TYPE
d
5
562
0
1
0
1
544.369
0.820997
590.509
0.820943
538.203
0.82089
571.461
0.820836
597.5
0.820783
590.17
0.820729
564.031
0.820676
576.458
0.820622
585.223
0.820568
560.228
0.820515
554.942
0.820461
566.841
0.820408
543.07
0.820354
571.041
0.820301
558.727
0.820247
561.744
0.820194
554.986
0.82014
587.669
0.820087
574.303
0.820033
570.954
0.81998
532.788
0.819927
543.192
0.819873
537.786
0.81982
539.679
0.819766
543.828
0.819713
552.143
0.819659
585.606
0.819606
551.279
0.819553
534.629
0.819499
558.865
0.819446
529.585
0.819392
518.228
0.819339
546.3
0.819286
611.912
0.819232
532.824
0.819179
552.826
0.819126
551.935
0.819072
540.448
0.819019
587.068
0.818966
545.134
0.818912
588.272
0.818859
567.391
0.818806
546.18
0.818752
543.921
0.818699
505.728
0.818646
537.588
0.818592
598.169
0.818539
522.097
0.818486
504.139
0.818432
572.578
0.818379
558.171
0.818326
551.225
0.818273
554.365
0.818219
535.944
0.818166
588.979
0.818113
601.082
0.81806
598.237
0.818007
595.66
0.817953
593.813
0.8179
557.739
0.817847
529.743
0.817794
572.136
0.81774
589.658
0.817687
537.946
0.817634
557.899
0.817581
576.136
0.817528
561.982
0.817475
604.524
0.817421
602.424
0.817368
560.807
0.817315
544.934
0.817262
581.001
0.817209
577.866
0.817156
555.877
0.817103
586.737
0.81705
592.522
0.816996
591.359
0.816943
589.318
0.81689
592.903
0.816837
602.465
0.816784
598.714
0.816731
598.641
0.816678
651.124
0.816625
589.145
0.816572
594.314
0.816519
602.243
0.816466
606.27
0.816413
608.45
0.81636
590.916
0.816307
657.923
0.816254
640.58
0.816201
584.99
0.816148
625.692
0.816095
623.11
0.816042
635.065
0.815989
601.881
0.815936
631.14
0.815883
638.613
0.81583
607.688
0.815777
652.956
0.815724
630.177
0.815671
608.036
0.815618
676.186
0.815565
670.361
0.815512
608.426
0.815459
584.149
0.815406
658.668
0.815353
645.404
0.8153
681.86
0.815248
626.329
0.815195
690.76
0.815142
641.457
0.815089
676.304
0.815036
720.144
0.814983
675.257
0.81493
751.54
0.814877
677.973
0.814825
776.801
0.814772
737.243
0.814719
713.614
0.814666
725.163
0.814613
767.743
0.81456
766.616
0.814508
792.328
0.814455
812.271
0.814402
797.306
0.814349
802.297
0.814296
789.721
0.814244
838.938
0.814191
788.609
0.814138
848.489
0.814085
841.454
0.814033
882.908
0.81398
909.813
0.813927
911.213
0.813874
946.335
0.813822
881.531
0.813769
1049.18
0.813716
1094.29
0.813664
1044.22
0.813611
1215.48
0.813558
1207.08
0.813505
1225.16
0.813453
1304.69
0.8134
1507.92
0.813347
1554.09
0.813295
1625.23
0.813242
1793.91
0.813189
1997.22
0.813137
2078.88
0.813084
2355.43
0.813032
2594.41
0.812979
2858.91
0.812926
3255.66
0.812874
3516.25
0.812821
3741.98
0.812769
3778.76
0.812716
3606.73
0.812663
2964.18
0.812611
2531.44
0.812558
1923.25
0.812506
1610.15
0.812453
1385.73
0.8124
1142.67
0.812348
1012.37
0.812295
992.337
0.812243
914.478
0.81219
917.193
0.812138
936.663
0.812085
947.759
0.812033
954.278
0.81198
936.389
0.811928
1033.02
0.811875
1128.45
0.811823
1155.94
0.81177
1185.39
0.811718
1269.05
0.811665
1372.83
0.811613
1603.78
0.81156
1655.47
0.811508
1864.36
0.811455
2026.62
0.811403
2288.16
0.811351
2482.69
0.811298
2711.45
0.811246
3112.65
0.811193
3530.83
0.811141
3886.27
0.811089
4411.14
0.811036
4433.43
0.810984
4152.09
0.810931
3611.67
0.810879
2824.08
0.810827
2096.53
0.810774
1472.53
0.810722
1103.66
0.81067
816.369
0.810617
659.278
0.810565
532.916
0.810512
461.281
0.81046
400.673
0.810408
409.999
0.810356
318.114
0.810303
340.09
0.810251
289.667
0.810199
286.713
0.810146
263.604
0.810094
273.313
0.810042
277.928
0.809989
201.945
0.809937
264.241
0.809885
222.286
0.809833
209.592
0.80978
217.259
0.809728
201.98
0.809676
236.912
0.809624
213.906
0.809572
184.519
0.809519
205.387
0.809467
183.939
0.809415
172.538
0.809363
182.707
0.80931
199.409
0.809258
205.937
0.809206
169.511
0.809154
167.813
0.809102
156.453
0.80905
186.115
0.808997
178.275
0.808945
156.958
0.808893
167.36
0.808841
152.523
0.808789
165.889
0.808737
167.865
0.808685
139.65
0.808633
164.277
0.80858
145.01
0.808528
172.453
0.808476
145.966
0.808424
161.002
0.808372
136.343
0.80832
135.013
0.808268
150.302
0.808216
157.914
0.808164
149.6
0.808112
147.93
0.80806
136.938
0.808008
135.614
0.807956
146.176
0.807904
139.339
0.807852
124.061
0.8078
123.886
0.807748
127.336
0.807696
109.536
0.807644
116.943
0.807592
117.622
0.80754
130.286
0.807488
141.258
0.807436
151.323
0.807384
129.823
0.807332
136.923
0.80728
130.962
0.807228
127.932
0.807176
125.491
0.807124
131.349
0.807072
114.942
0.80702
139.461
0.806968
104.079
0.806916
150.623
0.806864
118.742
0.806812
106.074
0.806761
131.895
0.806709
115
0.806657
111.211
0.806605
107.725
0.806553
119.597
0.806501
124.233
0.806449
129.505
0.806397
103.445
0.806346
120.363
0.806294
136.04
0.806242
end of experiment